Workbook

Sheet AP_Dashboard
A1: ACCOUNTS PAYABLE ANALYTICS Invoice Exceptions • Payment Performance • Overdue Risk

Sheet Invoices_Raw
A1: Invoice_ID | B1: Vendor_ID | C1: Invoice_Number | D1: PO_Number | E1: Invoice_Date | F1: Due_Date | G1: Invoice_Amount | H1: Currency | I1: Invoice_Status | J1: Modification_Required | K1: Source_Channel
A2: IN00001 | B2: V006 | C2: INV-V006-93886 | D2: PO-821590 | E2: 46259 | F2: 46274 | G2: 9560.85 | H2: INR | I2: Approved | J2: No | K2: Email
A3: IN00002 | B3: V008 | C3: INV-V008-18675 | D3: PO-321231 | E3: 46039 | F3: 46054 | G3: 20149.54 | H3: INR | I3: On Hold | J3: No | K3: EDI
A4: IN00003 | B4: V011 | C4: INV-V011-94259 | D4: PO-581141 | E4: 46131 | F4: 46161 | G4: 16427.31 | H4: INR | I4: Received | J4: Yes | K4: EDI
A5: IN00004 | B5: V018 | C5: INV-V018-86484 | D5: PO-518801 | E5: 46298 | F5: 46328 | G5: 6657.01 | H5: INR | I5: Approved | J5: No | K5: Email
A6: IN00005 | B6: V017 | C6: INV-V017-92240 | D6: PO-267753 | E6: 46275 | F6: 46305 | G6: 28837.72 | H6: INR | I6: Modified | J6: No | K6: Email
A7: IN00006 | B7: V013 | C7: INV-V013-42953 | D7: PO-680099 | E7: 46218 | F7: 46233 | G7: 14945.7 | H7: INR | I7: On Hold | J7: Yes | K7: EDI
A8: IN00007 | B8: V004 | C8: INV-V004-54587 | D8: PO-216970 | E8: 46297 | F8: 46327 | G8: 18801.84 | H8: INR | I8: Approved | J8: No | K8: Email
A9: IN00008 | B9: V009 | C9: INV-V009-23947 | D9: PO-755674 | E9: 46279 | F9: 46309 | G9: 19077.62 | H9: INR | I9: Approved | J9: No | K9: EDI
A10: IN00009 | B10: V007 | C10: INV-V007-79514 | D10: PO-100599 | E10: 46101 | F10: 46131 | G10: 9422.98 | H10: INR | I10: Approved | J10: No | K10: Email
A11: IN00010 | B11: V012 | C11: INV-V012-84364 | D11: PO-182582 | E11: 46180 | F11: 46225 | G11: 6077.57 | H11: INR | I11: Received | J11: No | K11: Email
A12: IN00011 | B12: V018 | C12: INV-V018-82063 | D12: PO-273148 | E12: 46087 | F12: 46117 | G12: 3314.38 | H12: INR | I12: Approved | J12: No | K12: Supplier Portal
A13: IN00012 | B13: V007 | C13: INV-V007-50857 | D13: PO-518373 | E13: 46299 | F13: 46329 | G13: 18911 | H13: INR | I13: On Hold | J13: No | K13: Supplier Portal
... A525: IN00524 | B525: V017 | C525: INV-V017-60293 | D525: PO-543588 | E525: 46222 | F525: 46252 | G525: 10525.79 | H525: INR | I525: Received | J525: No | K525: EDI

Sheet Payments_Raw
A1: Payment_ID | B1: Invoice_ID | C1: Vendor_ID | D1: Payment_Date | E1: Payment_Amount | F1: Payment_Status | G1: Failure_or_Pending_Reason | H1: Payment_Method | I1: Attempt_Number
A2: PAY00001 | B2: IN00191 | C2: V015 | E2: 0 | F2: Pending | G2: Awaiting approval | H2: Wire Transfer | I2: 1
A3: PAY00002 | B3: IN00337 | C3: V020 | E3: 0 | F3: Pending | G3: Account validation failed | H3: Wire Transfer | I3: 1
A4: PAY00003 | B4: IN00243 | C4: V002 | D4: 46118 | E4: 24655.09 | F4: Successful | H4: Wire Transfer | I4: 1
A5: PAY00004 | B5: IN00241 | C5: V015 | D5: 46156 | E5: 12889.61 | F5: Successful | H5: Wire Transfer | I5: 1
A6: PAY00005 | B6: IN00183 | C6: V014 | D6: 46120 | E6: 10833.51 | F6: Successful | H6: ACH | I6: 1
A7: PAY00006 | B7: IN00032 | C7: V003 | D7: 46121 | E7: 13694.29 | F7: Successful | H7: ACH | I7: 1
A8: PAY00007 | B8: IN00025 | C8: V009 | D8: 46292 | E8: 3376.25 | F8: Successful | H8: ACH | I8: 1
A9: PAY00008 | B9: IN00250 | C9: V019 | D9: 46220 | E9: 14487.57 | F9: Successful | H9: Bank Transfer | I9: 1
A10: PAY00009 | B10: IN00107 | C10: V009 | D10: 46087 | E10: 22484.84 | F10: Successful | H10: ACH | I10: 1
A11: PAY00010 | B11: IN00161 | C11: V017 | D11: 46123 | E11: 16193.1 | F11: Successful | H11: Bank Transfer | I11: 1
A12: PAY00011 | B12: IN00388 | C12: V005 | D12: 46111 | E12: 2252.4 | F12: Successful | H12: ACH | I12: 1
A13: PAY00012 | B13: IN00238 | C13: V007 | D13: 46178 | E13: 17046.91 | F13: Successful | H13: Bank Transfer | I13: 1
A14: PAY00013 | B14: IN00292 | C14: V012 | D14: 46170 | E14: 59426.29 | F14: Successful | H14: ACH | I14: 1
A15: PAY00014 | B15: IN00471 | C15: V001 | D15: 46105 | E15: 16763.19 | F15: Successful | H15: Bank Transfer | I15: 3
... A18: PAY00017 | B18: IN00366 | C18: V019 | D18: 46210 | E18: 24352.62 | F18: Successful | H18: ACH | I18: 1
A19: PAY00018 | B19: IN00367 | C19: V002 | E19: 0 | F19: Failed | G19: Payment batch queued | H19: Bank Transfer | I19: 2
A20: PAY00019 | B20: IN00489 | C20: V005 | E20: 0 | F20: Pending | G20: Invalid bank details | H20: ACH | I20: 2
A21: PAY00020 | B21: IN00446 | C21: V018 | D21: 46052 | E21: 20668.61 | F21: Successful | H21: ACH | I21: 2
A22: PAY00021 | B22: IN00516 | C22: V014 | E22: 0 | F22: Failed | G22: Payment rejected | H22: Wire Transfer | I22: 1
A23: PAY00022 | B23: IN00385 | C23: V020 | D23: 46277 | E23: 30979.13 | F23: Successful | H23: Bank Transfer | I23: 1
A24: PAY00023 | B24: IN00297 | C24: V004 | D24: 46065 | E24: 21247.6 | F24: Successful | H24: ACH | I24: 1
A25: PAY00024 | B25: IN00422 | C25: V004 | E25: 0 | F25: Pending | G25: Payment batch queued | H25: Bank Transfer | I25: 1
A26: PAY00025 | B26: IN00319 | C26: V007 | D26: 46347 | E26: 6801.2 | F26: Successful | H26: Bank Transfer | I26: 1
A27: PAY00026 | B27: IN00416 | C27: V019 | D27: 46070 | E27: 11868.83 | F27: Successful | H27: Wire Transfer | I27: 1
A28: PAY00027 | B28: IN00112 | C28: V005 | D28: 46118 | E28: 22596.68 | F28: Successful | H28: Bank Transfer | I28: 1
A29: PAY00028 | B29: IN00324 | C29: V017 | D29: 46286 | E29: 351.06 | F29: Successful | H29: Bank Transfer | I29: 3
A30: PAY00029 | B30: IN00156 | C30: V003 | D30: 46305 | E30: 49766.76 | F30: Successful | H30: ACH | I30: 2
A31: PAY00030 | B31: IN00339 | C31: V004 | D31: 46086 | E31: 8455.07 | F31: Successful | H31: Wire Transfer | I31: 1
A32: PAY00031 | B32: IN00523 | C32: V012 | D32: 46296 | E32: 11641.01 | F32: Successful | H32: Bank Transfer | I32: 1
A33: PAY00032 | B33: IN00455 | C33: V010 | D33: 46303 | E33: 20143.35 | F33: Successful | H33: ACH | I33: 1
A34: PAY00033 | B34: IN00361 | C34: V014 | D34: 46133 | E34: 8926.11 | F34: Successful | H34: ACH | I34: 2
A35: PAY00034 | B35: IN00498 | C35: V006 | D35: 46257 | E35: 16383.44 | F35: Successful | H35: Wire Transfer | I35: 1
A36: PAY00035 | B36: IN00099 | C36: V002 | D36: 46234 | E36: 18648.26 | F36: Successful | H36: ACH | I36: 1
A37: PAY00036 | B37: IN00230 | C37: V011 | D37: 46243 | E37: 11424.21 | F37: Successful | H37: Bank Transfer | I37: 1
... A49: PAY00048 | B49: IN00154 | C49: V003 | D49: 46354 | E49: 9685.92 | F49: Successful | H49: Bank Transfer | I49: 1
A50: PAY00049 | B50: IN00024 | C50: V003 | E50: 0 | F50: Failed | G50: Payment rejected | H50: Bank Transfer | I50: 3
A51: PAY00050 | B51: IN00029 | C51: V005 | D51: 46235 | E51: 7130.1 | F51: Successful | H51: ACH | I51: 1
A52: PAY00051 | B52: IN00289 | C52: V003 | D52: 46259 | E52: 16863.68 | F52: Successful | H52: Wire Transfer | I52: 1
A53: PAY00052 | B53: IN00085 | C53: V013 | D53: 46212 | E53: 12571.75 | F53: Successful | H53: Wire Transfer | I53: 1
...

Sheet Vendor_Master
A1: Vendor_ID | B1: Vendor_Name | C1: Vendor_Category | D1: Payment_Terms_Days | E1: Preferred_Payment_Method | F1: Vendor_Contact_Email | G1: Vendor_Status
A2: V001 | B2: Apex Office Supplies | C2: Professional Services | D2: 15 | E2: Bank Transfer | F2: ap-01@example.com | G2: Active
A3: V002 | B3: BluePeak Logistics | C3: Logistics | D3: 15 | E3: Bank Transfer | F3: ap-02@example.com | G3: Active
A4: V003 | B4: Cedar IT Services | C4: Professional Services | D4: 45 | E4: Wire Transfer | F4: ap-03@example.com | G4: Active
A5: V004 | B5: Delta Packaging | C5: Equipment | D5: 30 | E5: Bank Transfer | F5: ap-04@example.com | G5: Active
A6: V005 | B6: Evergreen Facilities | C6: Office Supplies | D6: 15 | E6: Bank Transfer | F6: ap-05@example.com | G6: Active
A7: V006 | B7: Fineline Components | C7: Equipment | D7: 15 | E7: Wire Transfer | F7: ap-06@example.com | G7: Under Review
A8: V007 | B8: Grove Industrial Tools | C8: Logistics | D8: 30 | E8: Wire Transfer | F8: ap-07@example.com | G8: Active
A9: V008 | B9: Harbor Freight Services | C9: Office Supplies | D9: 15 | E9: Wire Transfer | F9: ap-08@example.com | G9: Under Review
A10: V009 | B10: Indigo Marketing | C10: IT Services | D10: 30 | E10: Bank Transfer | F10: ap-09@example.com | G10: Active
A11: V010 | B11: Juniper Maintenance | C11: IT Services | D11: 15 | E11: Bank Transfer | F11: ap-10@example.com | G11: Under Review
A12: V011 | B12: Keystone Consulting | C12: Office Supplies | D12: 30 | E12: ACH | F12: ap-11@example.com | G12: Active
A13: V012 | B13: Lumen Electronics | C13: Office Supplies | D13: 45 | E13: ACH | F13: ap-12@example.com | G13: Active
... A21: V020 | B21: Vertex Utilities | C21: Equipment | D21: 45 | E21: Bank Transfer | F21: ap-20@example.com | G21: Active

Sheet Modification_Requests
A1: Request_ID | B1: Invoice_ID | C1: Vendor_ID | D1: Request_Date | E1: Request_Type | F1: Request_Status | G1: Resolution_Date | H1: Request_Notes
A2: MOD0001 | B2: IN00033 | C2: V012 | D2: 46058 | E2: Amount Correction | F2: Pending | H2: Missing or incorrect vendor details
A3: MOD0002 | B3: IN00441 | C3: V017 | D3: 46306 | E3: PO Reference Correction | F3: Completed | G3: 46309 | H3: Due date clarification requested
A4: MOD0003 | B4: IN00122 | C4: V012 | D4: 46314 | E4: Vendor Details Update | F4: Completed | G4: 46322 | H4: Invoice amount does not match PO
A5: MOD0004 | B5: IN00393 | C5: V011 | D5: 46074 | E5: Vendor Details Update | F5: Rejected | H5: Purchase order reference requires correction
A6: MOD0005 | B6: IN00461 | C6: V018 | D6: 46048 | E6: Due Date Correction | F6: Completed | G6: 46055 | H6: Missing or incorrect vendor details
A7: MOD0006 | B7: IN00323 | C7: V008 | D7: 46244 | E7: Due Date Correction | F7: Pending | H7: Invoice amount does not match PO
A8: MOD0007 | B8: IN00386 | C8: V016 | D8: 46281 | E8: Amount Correction | F8: Pending | H8: Due date clarification requested
A9: MOD0008 | B9: IN00454 | C9: V020 | D9: 46202 | E9: Tax Details Correction | F9: Rejected | H9: Missing or incorrect vendor details
A10: MOD0009 | B10: IN00471 | C10: V001 | D10: 46083 | E10: PO Reference Correction | F10: Completed | G10: 46092 | H10: Purchase order reference requires correction
A11: MOD0010 | B11: IN00037 | C11: V008 | D11: 46154 | E11: PO Reference Correction | F11: Completed | G11: 46158 | H11: Tax information requires review
A12: MOD0011 | B12: IN00034 | C12: V020 | D12: 46121 | E12: Due Date Correction | F12: Completed | G12: 46129 | H12: Due date clarification requested
A13: MOD0012 | B13: IN00182 | C13: V015 | D13: 46220 | E13: Due Date Correction | F13: Completed | G13: 46223 | H13: Due date clarification requested
A14: MOD0013 | B14: IN00311 | C14: V015 | D14: 46171 | E14: PO Reference Correction | F14: Completed | G14: 46182 | H14: Due date clarification requested
A15: MOD0014 | B15: IN00169 | C15: V015 | D15: 46214 | E15: Due Date Correction | F15: Rejected | H15: Invoice amount does not match PO
A16: MOD0015 | B16: IN00504 | C16: V008 | D16: 46068 | E16: Tax Details Correction | F16: Completed | G16: 46071 | H16: Missing or incorrect vendor details
A17: MOD0016 | B17: IN00442 | C17: V013 | D17: 46108 | E17: Tax Details Correction | F17: Completed | G17: 46115 | H17: Purchase order reference requires correction
A18: MOD0017 | B18: IN00138 | C18: V020 | D18: 46310 | E18: Vendor Details Update | F18: Needs Vendor Response | H18: Tax information requires review
A19: MOD0018 | B19: IN00320 | C19: V011 | D19: 46056 | E19: Vendor Details Update | F19: Completed | G19: 46061 | H19: Due date clarification requested
A20: MOD0019 | B20: IN00399 | C20: V015 | D20: 46194 | E20: Amount Correction | F20: Completed | G20: 46197 | H20: Missing or incorrect vendor details
A21: MOD0020 | B21: IN00500 | C21: V005 | D21: 46257 | E21: Tax Details Correction | F21: Completed | G21: 46265 | H21: Due date clarification requested
A22: MOD0021 | B22: IN00113 | C22: V005 | D22: 46082 | E22: Amount Correction | F22: Needs Vendor Response | H22: Missing or incorrect vendor details
A23: MOD0022 | B23: IN00503 | C23: V004 | D23: 46044 | E23: Amount Correction | F23: Completed | G23: 46049 | H23: Purchase order reference requires correction
A24: MOD0023 | B24: IN00482 | C24: V005 | D24: 46091 | E24: Amount Correction | F24: Pending | H24: Tax information requires review
A25: MOD0024 | B25: IN00488 | C25: V014 | D25: 46110 | E25: Amount Correction | F25: Rejected | H25: Purchase order reference requires correction
A26: MOD0025 | B26: IN00161 | C26: V017 | D26: 46072 | E26: Tax Details Correction | F26: Pending | H26: Purchase order reference requires correction
A27: MOD0026 | B27: IN00519 | C27: V007 | D27: 46303 | E27: Tax Details Correction | F27: Pending | H27: Missing or incorrect vendor details
A28: MOD0027 | B28: IN00058 | C28: V015 | D28: 46134 | E28: Due Date Correction | F28: Completed | G28: 46136 | H28: Due date clarification requested
A29: MOD0028 | B29: IN00401 | C29: V013 | D29: 46110 | E29: Due Date Correction | F29: Pending | H29: Purchase order reference requires correction
A30: MOD0029 | B30: IN00270 | C30: V002 | D30: 46072 | E30: Vendor Details Update | F30: Completed | G30: 46082 | H30: Invoice amount does not match PO
A31: MOD0030 | B31: IN00507 | C31: V012 | D31: 46147 | E31: PO Reference Correction | F31: Rejected | H31: Due date clarification requested
A32: MOD0031 | B32: IN00387 | C32: V012 | D32: 46125 | E32: Tax Details Correction | F32: Rejected | H32: Missing or incorrect vendor details
A33: MOD0032 | B33: IN00362 | C33: V020 | D33: 46153 | E33: Vendor Details Update | F33: Completed | G33: 46158 | H33: Tax information requires review
A34: MOD0033 | B34: IN00292 | C34: V012 | D34: 46126 | E34: Amount Correction | F34: Completed | G34: 46134 | H34: Due date clarification requested
A35: MOD0034 | B35: IN00329 | C35: V020 | D35: 46171 | E35: PO Reference Correction | F35: Completed | G35: 46180 | H35: Tax information requires review
A36: MOD0035 | B36: IN00063 | C36: V013 | D36: 46233 | E36: PO Reference Correction | F36: Completed | G36: 46236 | H36: Purchase order reference requires correction
A37: MOD0036 | B37: IN00029 | C37: V005 | D37: 46173 | E37: PO Reference Correction | F37: Completed | G37: 46174 | H37: Due date clarification requested
A38: MOD0037 | B38: IN00047 | C38: V015 | D38: 46236 | E38: Vendor Details Update | F38: Completed | G38: 46241 | H38: Due date clarification requested
A39: MOD0038 | B39: IN00132 | C39: V018 | D39: 46153 | E39: PO Reference Correction | F39: Completed | G39: 46164 | H39: Invoice amount does not match PO
A40: MOD0039 | B40: IN00376 | C40: V008 | D40: 46083 | E40: Tax Details Correction | F40: Completed | G40: 46090 | H40: Invoice amount does not match PO
...

Sheet Data_Dictionary
A1: Sheet | B1: Field | C1: Description
A2: Invoices_Raw | B2: Invoice_ID | C2: Identifier for an invoice submission; duplicate submissions may share Vendor_ID + Invoice_Number.
A3: Invoices_Raw | B3: Vendor_ID | C3: Vendor key linking to Vendor_Master.
A4: Invoices_Raw | B4: Invoice_Number | C4: Supplier invoice number; combine with Vendor_ID to detect duplicates.
A5: Invoices_Raw | B5: Invoice_Amount | C5: Expected invoice amount in INR.
A6: Invoices_Raw | B6: Due_Date | C6: Payment due date.
A7: Payments_Raw | B7: Invoice_ID | C7: Invoice linked to a payment attempt.
A8: Payments_Raw | B8: Payment_Status | C8: Successful, Failed, or Pending.
A9: Payments_Raw | B9: Payment_Amount | C9: Successful payment amount; failed/pending rows contain zero.
A10: Payments_Raw | B10: Failure_or_Pending_Reason | C10: Recorded reason for failed or pending payment.
A11: Modification_Requests | B11: Request_Status | C11: Completed, Pending, Rejected, or Needs Vendor Response.
A12: Vendor_Master | B12: Payment_Terms_Days | C12: Payment terms used to calculate due dates.
A13: Project | B13: As-of date | C13: Use 14-Oct-2026 for overdue calculations.

Sheet PT_Exceptions
A3: Row Labels | B3: Count of Invoice_ID
A4: Amount Mismatch | B4: 11
A5: Duplicate Invoice | B5: 48
A6: Failed Payment | B6: 37
A7: No Exception | B7: 293
A8: Pending Payment | B8: 37
A9: Unpaid Invoice | B9: 98
A10: Grand Total | B10: 524

Sheet PT_Payments
A3: Row Labels | B3: Count of Invoice_ID
A4: Failed | B4: 40
A5: Paid | B5: 322
A6: Partial Payment | B6: 13
A7: Pending | B7: 45
A8: Unpaid | B8: 104
A9: Grand Total | B9: 524

Sheet PT_Overdue
A3: Sum of Amount Difference | B3: Column Labels
A4: Row Labels | B4: Overdue | C4: Grand Total
A5: V003 | B5: 132412.45 | C5: 132412.45
A6: V019 | B6: 135602.42 | C6: 135602.42
A7: V012 | B7: 136603.19 | C7: 136603.19
A8: V013 | B8: 137648.68 | C8: 137648.68
A9: V004 | B9: 138593.79 | C9: 138593.79
A10: V001 | B10: 142389.78 | C10: 142389.78
A11: V010 | B11: 148754.42 | C11: 148754.42
A12: V015 | B12: 172592.45 | C12: 172592.45
A13: V005 | B13: 184860.98 | C13: 184860.98
A14: V014 | B14: 200808.62 | C14: 200808.62
A15: Grand Total | B15: 1530266.8 | C15: 1530266.8

Sheet Invoice_Analysis
A1: Invoice_ID | B1: Vendor_ID | C1: Invoice_Number | D1: PO_Number | E1: Invoice_Date | F1: Due_Date | G1: Invoice_Amount | H1: Currency | I1: Invoice_Status | J1: Modification_Required | K1: Source_Channel | L1: Duplicate Flag | M1: Payment Status | N1: Total Paid | O1: Amount Difference | P1: Exception Type | Q1: Overdue Status | R1: Column1
A2: IN00001 | B2: V006 | C2: INV-V006-93886 | D2: PO-821590 | E2: 46259 | F2: 46274 | G2: 9560.85 | H2: INR | I2: Approved | J2: No | K2: Email | L2: =IF(COUNTIFS($B:$B,B2,$C:$C,C2)>1,"Duplicate","Unique") -> Unique | M2: =IF(COUNTIF(Payments_Raw!$B:$B,A2)=0,"Unpaid",IF(N2>=G2,"Paid",IF(N2>0,"Partial Payment",IF(COUNTIFS(Payments_Raw!$B:$B,A2,Payments_Raw!$F:$F,"Failed")>0,"Failed",IF(COUNTIFS(Payments_Raw!$B:$B,A2,Payments_Raw!$F:$F,"Pending")>0,"Pending","Unpaid"))))) -> Unpaid | N2: =SUMIFS(Payments_Raw!$E:$E,Payments_Raw!$B:$B,A2,Payments_Raw!$F:$F,"Successful") -> 0 | O2: =G2-N2 -> 9560.85 | P2: =IF(L2="Duplicate","Duplicate Invoice",IF(M2="Failed","Failed Payment",IF(M2="Pending","Pending Payment",IF(M2="Unpaid","Unpaid Invoice",IF(M2="Partial Payment","Amount Mismatch","No Exception"))))) -> Unpaid Invoice | Q2: =IF(AND(G2<DATE(2026,10,14),M2<>"Paid"),"Overdue","Not Overdue") -> Overdue
A3: IN00002 | B3: V008 | C3: INV-V008-18675 | D3: PO-321231 | E3: 46039 | F3: 46054 | G3: 20149.54 | H3: INR | I3: On Hold | J3: No | K3: EDI | L3: =IF(COUNTIFS($B:$B,B3,$C:$C,C3)>1,"Duplicate","Unique") -> Unique | M3: =IF(COUNTIF(Payments_Raw!$B:$B,A3)=0,"Unpaid",IF(N3>=G3,"Paid",IF(N3>0,"Partial Payment",IF(COUNTIFS(Payments_Raw!$B:$B,A3,Payments_Raw!$F:$F,"Failed")>0,"Failed",IF(COUNTIFS(Payments_Raw!$B:$B,A3,Payments_Raw!$F:$F,"Pending")>0,"Pending","Unpaid"))))) -> Paid | N3: =SUMIFS(Payments_Raw!$E:$E,Payments_Raw!$B:$B,A3,Payments_Raw!$F:$F,"Successful") -> 20149.54 | O3: =G3-N3 -> 0 | P3: =IF(L3="Duplicate","Duplicate Invoice",IF(M3="Failed","Failed Payment",IF(M3="Pending","Pending Payment",IF(M3="Unpaid","Unpaid Invoice",IF(M3="Partial Payment","Amount Mismatch","No Exception"))))) -> No Exception | Q3: =IF(AND(G3<DATE(2026,10,14),M3<>"Paid"),"Overdue","Not Overdue") -> Not Overdue | R3: =48/524 -> 0.091603053
A4: IN00003 | B4: V011 | C4: INV-V011-94259 | D4: PO-581141 | E4: 46131 | F4: 46161 | G4: 16427.31 | H4: INR | I4: Received | J4: Yes | K4: EDI | L4: =IF(COUNTIFS($B:$B,B4,$C:$C,C4)>1,"Duplicate","Unique") -> Unique | M4: =IF(COUNTIF(Payments_Raw!$B:$B,A4)=0,"Unpaid",IF(N4>=G4,"Paid",IF(N4>0,"Partial Payment",IF(COUNTIFS(Payments_Raw!$B:$B,A4,Payments_Raw!$F:$F,"Failed")>0,"Failed",IF(COUNTIFS(Payments_Raw!$B:$B,A4,Payments_Raw!$F:$F,"Pending")>0,"Pending","Unpaid"))))) -> Unpaid | N4: =SUMIFS(Payments_Raw!$E:$E,Payments_Raw!$B:$B,A4,Payments_Raw!$F:$F,"Successful") -> 0 | O4: =G4-N4 -> 16427.31 | P4: =IF(L4="Duplicate","Duplicate Invoice",IF(M4="Failed","Failed Payment",IF(M4="Pending","Pending Payment",IF(M4="Unpaid","Unpaid Invoice",IF(M4="Partial Payment","Amount Mismatch","No Exception"))))) -> Unpaid Invoice | Q4: =IF(AND(G4<DATE(2026,10,14),M4<>"Paid"),"Overdue","Not Overdue") -> Overdue | R4: =COUNTIF(Invoice_Analysis!Q:Q,"Overdue") -> 198
A5: IN00004 | B5: V018 | C5: INV-V018-86484 | D5: PO-518801 | E5: 46298 | F5: 46328 | G5: 6657.01 | H5: INR | I5: Approved | J5: No | K5: Email | L5: =IF(COUNTIFS($B:$B,B5,$C:$C,C5)>1,"Duplicate","Unique") -> Unique | M5: =IF(COUNTIF(Payments_Raw!$B:$B,A5)=0,"Unpaid",IF(N5>=G5,"Paid",IF(N5>0,"Partial Payment",IF(COUNTIFS(Payments_Raw!$B:$B,A5,Payments_Raw!$F:$F,"Failed")>0,"Failed",IF(COUNTIFS(Payments_Raw!$B:$B,A5,Payments_Raw!$F:$F,"Pending")>0,"Pending","Unpaid"))))) -> Unpaid | N5: =SUMIFS(Payments_Raw!$E:$E,Payments_Raw!$B:$B,A5,Payments_Raw!$F:$F,"Successful") -> 0 | O5: =G5-N5 -> 6657.01 | P5: =IF(L5="Duplicate","Duplicate Invoice",IF(M5="Failed","Failed Payment",IF(M5="Pending","Pending Payment",IF(M5="Unpaid","Unpaid Invoice",IF(M5="Partial Payment","Amount Mismatch","No Exception"))))) -> Unpaid Invoice | Q5: =IF(AND(G5<DATE(2026,10,14),M5<>"Paid"),"Overdue","Not Overdue") -> Overdue | R5: =COUNTIF(Invoice_Analysis!L:L,"Duplicate") -> 48
A6: IN00005 | B6: V017 | C6: INV-V017-92240 | D6: PO-267753 | E6: 46275 | F6: 46305 | G6: 28837.72 | H6: INR | I6: Modified | J6: No | K6: Email | L6: =IF(COUNTIFS($B:$B,B6,$C:$C,C6)>1,"Duplicate","Unique") -> Unique | M6: =IF(COUNTIF(Payments_Raw!$B:$B,A6)=0,"Unpaid",IF(N6>=G6,"Paid",IF(N6>0,"Partial Payment",IF(COUNTIFS(Payments_Raw!$B:$B,A6,Payments_Raw!$F:$F,"Failed")>0,"Failed",IF(COUNTIFS(Payments_Raw!$B:$B,A6,Payments_Raw!$F:$F,"Pending")>0,"Pending","Unpaid"))))) -> Paid | N6: =SUMIFS(Payments_Raw!$E:$E,Payments_Raw!$B:$B,A6,Payments_Raw!$F:$F,"Successful") -> 28837.72 | O6: =G6-N6 -> 0 | P6: =IF(L6="Duplicate","Duplicate Invoice",IF(M6="Failed","Failed Payment",IF(M6="Pending","Pending Payment",IF(M6="Unpaid","Unpaid Invoice",IF(M6="Partial Payment","Amount Mismatch","No Exception"))))) -> No Exception | Q6: =IF(AND(G6<DATE(2026,10,14),M6<>"Paid"),"Overdue","Not Overdue") -> Not Overdue
A7: IN00006 | B7: V013 | C7: INV-V013-42953 | D7: PO-680099 | E7: 46218 | F7: 46233 | G7: 14945.7 | H7: INR | I7: On Hold | J7: Yes | K7: EDI | L7: =IF(COUNTIFS($B:$B,B7,$C:$C,C7)>1,"Duplicate","Unique") -> Unique | M7: =IF(COUNTIF(Payments_Raw!$B:$B,A7)=0,"Unpaid",IF(N7>=G7,"Paid",IF(N7>0,"Partial Payment",IF(COUNTIFS(Payments_Raw!$B:$B,A7,Payments_Raw!$F:$F,"Failed")>0,"Failed",IF(COUNTIFS(Payments_Raw!$B:$B,A7,Payments_Raw!$F:$F,"Pending")>0,"Pending","Unpaid"))))) -> Paid | N7: =SUMIFS(Payments_Raw!$E:$E,Payments_Raw!$B:$B,A7,Payments_Raw!$F:$F,"Successful") -> 14945.7 | O7: =G7-N7 -> 0 | P7: =IF(L7="Duplicate","Duplicate Invoice",IF(M7="Failed","Failed Payment",IF(M7="Pending","Pending Payment",IF(M7="Unpaid","Unpaid Invoice",IF(M7="Partial Payment","Amount Mismatch","No Exception"))))) -> No Exception | Q7: =IF(AND(G7<DATE(2026,10,14),M7<>"Paid"),"Overdue","Not Overdue") -> Not Overdue
A8: IN00007 | B8: V004 | C8: INV-V004-54587 | D8: PO-216970 | E8: 46297 | F8: 46327 | G8: 18801.84 | H8: INR | I8: Approved | J8: No | K8: Email | L8: =IF(COUNTIFS($B:$B,B8,$C:$C,C8)>1,"Duplicate","Unique") -> Unique | M8: =IF(COUNTIF(Payments_Raw!$B:$B,A8)=0,"Unpaid",IF(N8>=G8,"Paid",IF(N8>0,"Partial Payment",IF(COUNTIFS(Payments_Raw!$B:$B,A8,Payments_Raw!$F:$F,"Failed")>0,"Failed",IF(COUNTIFS(Payments_Raw!$B:$B,A8,Payments_Raw!$F:$F,"Pending")>0,"Pending","Unpaid"))))) -> Paid | N8: =SUMIFS(Payments_Raw!$E:$E,Payments_Raw!$B:$B,A8,Payments_Raw!$F:$F,"Successful") -> 18801.84 | O8: =G8-N8 -> 0 | P8: =IF(L8="Duplicate","Duplicate Invoice",IF(M8="Failed","Failed Payment",IF(M8="Pending","Pending Payment",IF(M8="Unpaid","Unpaid Invoice",IF(M8="Partial Payment","Amount Mismatch","No Exception"))))) -> No Exception | Q8: =IF(AND(G8<DATE(2026,10,14),M8<>"Paid"),"Overdue","Not Overdue") -> Not Overdue
A9: IN00008 | B9: V009 | C9: INV-V009-23947 | D9: PO-755674 | E9: 46279 | F9: 46309 | G9: 19077.62 | H9: INR | I9: Approved | J9: No | K9: EDI | L9: =IF(COUNTIFS($B:$B,B9,$C:$C,C9)>1,"Duplicate","Unique") -> Unique | M9: =IF(COUNTIF(Payments_Raw!$B:$B,A9)=0,"Unpaid",IF(N9>=G9,"Paid",IF(N9>0,"Partial Payment",IF(COUNTIFS(Payments_Raw!$B:$B,A9,Payments_Raw!$F:$F,"Failed")>0,"Failed",IF(COUNTIFS(Payments_Raw!$B:$B,A9,Payments_Raw!$F:$F,"Pending")>0,"Pending","Unpaid"))))) -> Paid | N9: =SUMIFS(Payments_Raw!$E:$E,Payments_Raw!$B:$B,A9,Payments_Raw!$F:$F,"Successful") -> 19077.62 | O9: =G9-N9 -> 0 | P9: =IF(L9="Duplicate","Duplicate Invoice",IF(M9="Failed","Failed Payment",IF(M9="Pending","Pending Payment",IF(M9="Unpaid","Unpaid Invoice",IF(M9="Partial Payment","Amount Mismatch","No Exception"))))) -> No Exception | Q9: =IF(AND(G9<DATE(2026,10,14),M9<>"Paid"),"Overdue","Not Overdue") -> Not Overdue
A10: IN00009 | B10: V007 | C10: INV-V007-79514 | D10: PO-100599 | E10: 46101 | F10: 46131 | G10: 9422.98 | H10: INR | I10: Approved | J10: No | K10: Email | L10: =IF(COUNTIFS($B:$B,B10,$C:$C,C10)>1,"Duplicate","Unique") -> Unique | M10: =IF(COUNTIF(Payments_Raw!$B:$B,A10)=0,"Unpaid",IF(N10>=G10,"Paid",IF(N10>0,"Partial Payment",IF(COUNTIFS(Payments_Raw!$B:$B,A10,Payments_Raw!$F:$F,"Failed")>0,"Failed",IF(COUNTIFS(Payments_Raw!$B:$B,A10,Payments_Raw!$F:$F,"Pending")>0,"Pending","Unpaid"))))) -> Unpaid | N10: =SUMIFS(Payments_Raw!$E:$E,Payments_Raw!$B:$B,A10,Payments_Raw!$F:$F,"Successful") -> 0 | O10: =G10-N10 -> 9422.98 | P10: =IF(L10="Duplicate","Duplicate Invoice",IF(M10="Failed","Failed Payment",IF(M10="Pending","Pending Payment",IF(M10="Unpaid","Unpaid Invoice",IF(M10="Partial Payment","Amount Mismatch","No Exception"))))) -> Unpaid Invoice | Q10: =IF(AND(G10<DATE(2026,10,14),M10<>"Paid"),"Overdue","Not Overdue") -> Overdue
A11: IN00010 | B11: V012 | C11: INV-V012-84364 | D11: PO-182582 | E11: 46180 | F11: 46225 | G11: 6077.57 | H11: INR | I11: Received | J11: No | K11: Email | L11: =IF(COUNTIFS($B:$B,B11,$C:$C,C11)>1,"Duplicate","Unique") -> Unique | M11: =IF(COUNTIF(Payments_Raw!$B:$B,A11)=0,"Unpaid",IF(N11>=G11,"Paid",IF(N11>0,"Partial Payment",IF(COUNTIFS(Payments_Raw!$B:$B,A11,Payments_Raw!$F:$F,"Failed")>0,"Failed",IF(COUNTIFS(Payments_Raw!$B:$B,A11,Payments_Raw!$F:$F,"Pending")>0,"Pending","Unpaid"))))) -> Paid | N11: =SUMIFS(Payments_Raw!$E:$E,Payments_Raw!$B:$B,A11,Payments_Raw!$F:$F,"Successful") -> 6077.57 | O11: =G11-N11 -> 0 | P11: =IF(L11="Duplicate","Duplicate Invoice",IF(M11="Failed","Failed Payment",IF(M11="Pending","Pending Payment",IF(M11="Unpaid","Unpaid Invoice",IF(M11="Partial Payment","Amount Mismatch","No Exception"))))) -> No Exception | Q11: =IF(AND(G11<DATE(2026,10,14),M11<>"Paid"),"Overdue","Not Overdue") -> Not Overdue
A12: IN00011 | B12: V018 | C12: INV-V018-82063 | D12: PO-273148 | E12: 46087 | F12: 46117 | G12: 3314.38 | H12: INR | I12: Approved | J12: No | K12: Supplier Portal | L12: =IF(COUNTIFS($B:$B,B12,$C:$C,C12)>1,"Duplicate","Unique") -> Unique | M12: =IF(COUNTIF(Payments_Raw!$B:$B,A12)=0,"Unpaid",IF(N12>=G12,"Paid",IF(N12>0,"Partial Payment",IF(COUNTIFS(Payments_Raw!$B:$B,A12,Payments_Raw!$F:$F,"Failed")>0,"Failed",IF(COUNTIFS(Payments_Raw!$B:$B,A12,Payments_Raw!$F:$F,"Pending")>0,"Pending","Unpaid"))))) -> Pending | N12: =SUMIFS(Payments_Raw!$E:$E,Payments_Raw!$B:$B,A12,Payments_Raw!$F:$F,"Successful") -> 0 | O12: =G12-N12 -> 3314.38 | P12: =IF(L12="Duplicate","Duplicate Invoice",IF(M12="Failed","Failed Payment",IF(M12="Pending","Pending Payment",IF(M12="Unpaid","Unpaid Invoice",IF(M12="Partial Payment","Amount Mismatch","No Exception"))))) -> Pending Payment | Q12: =IF(AND(G12<DATE(2026,10,14),M12<>"Paid"),"Overdue","Not Overdue") -> Overdue
A13: IN00012 | B13: V007 | C13: INV-V007-50857 | D13: PO-518373 | E13: 46299 | F13: 46329 | G13: 18911 | H13: INR | I13: On Hold | J13: No | K13: Supplier Portal | L13: =IF(COUNTIFS($B:$B,B13,$C:$C,C13)>1,"Duplicate","Unique") -> Duplicate | M13: =IF(COUNTIF(Payments_Raw!$B:$B,A13)=0,"Unpaid",IF(N13>=G13,"Paid",IF(N13>0,"Partial Payment",IF(COUNTIFS(Payments_Raw!$B:$B,A13,Payments_Raw!$F:$F,"Failed")>0,"Failed",IF(COUNTIFS(Payments_Raw!$B:$B,A13,Payments_Raw!$F:$F,"Pending")>0,"Pending","Unpaid"))))) -> Partial Payment | N13: =SUMIFS(Payments_Raw!$E:$E,Payments_Raw!$B:$B,A13,Payments_Raw!$F:$F,"Successful") -> 17398.12 | O13: =G13-N13 -> 1512.88 | P13: =IF(L13="Duplicate","Duplicate Invoice",IF(M13="Failed","Failed Payment",IF(M13="Pending","Pending Payment",IF(M13="Unpaid","Unpaid Invoice",IF(M13="Partial Payment","Amount Mismatch","No Exception"))))) -> Duplicate Invoice | Q13: =IF(AND(G13<DATE(2026,10,14),M13<>"Paid"),"Overdue","Not Overdue") -> Overdue
A14: IN00013 | B14: V017 | C14: INV-V017-54313 | D14: PO-122056 | E14: 46254 | F14: 46284 | G14: 3130.58 | H14: INR | I14: Approved | J14: No | K14: Email | L14: =IF(COUNTIFS($B:$B,B14,$C:$C,C14)>1,"Duplicate","Unique") -> Unique | M14: =IF(COUNTIF(Payments_Raw!$B:$B,A14)=0,"Unpaid",IF(N14>=G14,"Paid",IF(N14>0,"Partial Payment",IF(COUNTIFS(Payments_Raw!$B:$B,A14,Payments_Raw!$F:$F,"Failed")>0,"Failed",IF(COUNTIFS(Payments_Raw!$B:$B,A14,Payments_Raw!$F:$F,"Pending")>0,"Pending","Unpaid"))))) -> Paid | N14: =SUMIFS(Payments_Raw!$E:$E,Payments_Raw!$B:$B,A14,Payments_Raw!$F:$F,"Successful") -> 3130.58 | O14: =G14-N14 -> 0 | P14: =IF(L14="Duplicate","Duplicate Invoice",IF(M14="Failed","Failed Payment",IF(M14="Pending","Pending Payment",IF(M14="Unpaid","Unpaid Invoice",IF(M14="Partial Payment","Amount Mismatch","No Exception"))))) -> No Exception | Q14: =IF(AND(G14<DATE(2026,10,14),M14<>"Paid"),"Overdue","Not Overdue") -> Not Overdue
A15: IN00014 | B15: V001 | C15: INV-V001-14117 | D15: PO-446479 | E15: 46059 | F15: 46074 | G15: 27359.01 | H15: INR | I15: Received | J15: No | K15: EDI | L15: =IF(COUNTIFS($B:$B,B15,$C:$C,C15)>1,"Duplicate","Unique") -> Unique | M15: =IF(COUNTIF(Payments_Raw!$B:$B,A15)=0,"Unpaid",IF(N15>=G15,"Paid",IF(N15>0,"Partial Payment",IF(COUNTIFS(Payments_Raw!$B:$B,A15,Payments_Raw!$F:$F,"Failed")>0,"Failed",IF(COUNTIFS(Payments_Raw!$B:$B,A15,Payments_Raw!$F:$F,"Pending")>0,"Pending","Unpaid"))))) -> Paid | N15: =SUMIFS(Payments_Raw!$E:$E,Payments_Raw!$B:$B,A15,Payments_Raw!$F:$F,"Successful") -> 27359.01 | O15: =G15-N15 -> 0 | P15: =IF(L15="Duplicate","Duplicate Invoice",IF(M15="Failed","Failed Payment",IF(M15="Pending","Pending Payment",IF(M15="Unpaid","Unpaid Invoice",IF(M15="Partial Payment","Amount Mismatch","No Exception"))))) -> No Exception | Q15: =IF(AND(G15<DATE(2026,10,14),M15<>"Paid"),"Overdue","Not Overdue") -> Not Overdue
A16: IN00015 | B16: V016 | C16: INV-V016-84847 | D16: PO-704201 | E16: 46132 | F16: 46147 | G16: 13536.14 | H16: INR | I16: Approved | J16: No | K16: Supplier Portal | L16: =IF(COUNTIFS($B:$B,B16,$C:$C,C16)>1,"Duplicate","Unique") -> Unique | M16: =IF(COUNTIF(Payments_Raw!$B:$B,A16)=0,"Unpaid",IF(N16>=G16,"Paid",IF(N16>0,"Partial Payment",IF(COUNTIFS(Payments_Raw!$B:$B,A16,Payments_Raw!$F:$F,"Failed")>0,"Failed",IF(COUNTIFS(Payments_Raw!$B:$B,A16,Payments_Raw!$F:$F,"Pending")>0,"Pending","Unpaid"))))) -> Paid | N16: =SUMIFS(Payments_Raw!$E:$E,Payments_Raw!$B:$B,A16,Payments_Raw!$F:$F,"Successful") -> 13536.14 | O16: =G16-N16 -> 0 | P16: =IF(L16="Duplicate","Duplicate Invoice",IF(M16="Failed","Failed Payment",IF(M16="Pending","Pending Payment",IF(M16="Unpaid","Unpaid Invoice",IF(M16="Partial Payment","Amount Mismatch","No Exception"))))) -> No Exception | Q16: =IF(AND(G16<DATE(2026,10,14),M16<>"Paid"),"Overdue","Not Overdue") -> Not Overdue
A17: IN00016 | B17: V007 | C17: INV-V007-65519 | D17: PO-531071 | E17: 46071 | F17: 46101 | G17: 2531.64 | H17: INR | I17: Approved | J17: No | K17: EDI | L17: =IF(COUNTIFS($B:$B,B17,$C:$C,C17)>1,"Duplicate","Unique") -> Unique | M17: =IF(COUNTIF(Payments_Raw!$B:$B,A17)=0,"Unpaid",IF(N17>=G17,"Paid",IF(N17>0,"Partial Payment",IF(COUNTIFS(Payments_Raw!$B:$B,A17,Payments_Raw!$F:$F,"Failed")>0,"Failed",IF(COUNTIFS(Payments_Raw!$B:$B,A17,Payments_Raw!$F:$F,"Pending")>0,"Pending","Unpaid"))))) -> Paid | N17: =SUMIFS(Payments_Raw!$E:$E,Payments_Raw!$B:$B,A17,Payments_Raw!$F:$F,"Successful") -> 2531.64 | O17: =G17-N17 -> 0 | P17: =IF(L17="Duplicate","Duplicate Invoice",IF(M17="Failed","Failed Payment",IF(M17="Pending","Pending Payment",IF(M17="Unpaid","Unpaid Invoice",IF(M17="Partial Payment","Amount Mismatch","No Exception"))))) -> No Exception | Q17: =IF(AND(G17<DATE(2026,10,14),M17<>"Paid"),"Overdue","Not Overdue") -> Not Overdue
... A495: IN00494 | B495: V020 | C495: INV-V020-30869 | D495: PO-287847 | E495: 46107 | F495: 46152 | G495: 18959.29 | H495: INR | I495: Approved | J495: No | K495: Email | L495: =IF(COUNTIFS($B:$B,B495,$C:$C,C495)>1,"Duplicate","Unique") -> Unique | M495: =IF(COUNTIF(Payments_Raw!$B:$B,A495)=0,"Unpaid",IF(N495>=G495,"Paid",IF(N495>0,"Partial Payment",IF(COUNTIFS(Payments_Raw!$B:$B,A495,Payments_Raw!$F:$F,"Failed")>0,"Failed",IF(COUNTIFS(Payments_Raw!$B:$B,A495,Payments_Raw!$F:$F,"Pending")>0,"Pending","Unpaid"))))) -> Unpaid | N495: =SUMIFS(Payments_Raw!$E:$E,Payments_Raw!$B:$B,A495,Payments_Raw!$F:$F,"Successful") -> 0 | O495: =G495-N495 -> 18959.29 | P495: =IF(L495="Duplicate","Duplicate Invoice",IF(M495="Failed","Failed Payment",IF(M495="Pending","Pending Payment",IF(M495="Unpaid","Unpaid Invoice",IF(M495="Partial Payment","Amount Mismatch","No Exception"))))) -> Unpaid Invoice | Q495: =IF(AND(G495<DATE(2026,10,14),M495<>"Paid"),"Overdue","Not Overdue") -> Overdue
A496: IN00495 | B496: V016 | C496: INV-V016-40375 | D496: PO-165914 | E496: 46206 | F496: 46221 | G496: 1125.65 | H496: INR | I496: Approved | J496: No | K496: EDI | L496: =IF(COUNTIFS($B:$B,B496,$C:$C,C496)>1,"Duplicate","Unique") -> Unique | M496: =IF(COUNTIF(Payments_Raw!$B:$B,A496)=0,"Unpaid",IF(N496>=G496,"Paid",IF(N496>0,"Partial Payment",IF(COUNTIFS(Payments_Raw!$B:$B,A496,Payments_Raw!$F:$F,"Failed")>0,"Failed",IF(COUNTIFS(Payments_Raw!$B:$B,A496,Payments_Raw!$F:$F,"Pending")>0,"Pending","Unpaid"))))) -> Paid | N496: =SUMIFS(Payments_Raw!$E:$E,Payments_Raw!$B:$B,A496,Payments_Raw!$F:$F,"Successful") -> 1125.65 | O496: =G496-N496 -> 0 | P496: =IF(L496="Duplicate","Duplicate Invoice",IF(M496="Failed","Failed Payment",IF(M496="Pending","Pending Payment",IF(M496="Unpaid","Unpaid Invoice",IF(M496="Partial Payment","Amount Mismatch","No Exception"))))) -> No Exception | Q496: =IF(AND(G496<DATE(2026,10,14),M496<>"Paid"),"Overdue","Not Overdue") -> Not Overdue | S496: =COUNTA(Invoice_Analysis!A:A)-1 -> 524
A497: IN00496 | B497: V007 | C497: INV-V007-71561 | D497: PO-576728 | E497: 46288 | F497: 46318 | G497: 22704.23 | H497: INR | I497: On Hold | J497: Yes | K497: EDI | L497: =IF(COUNTIFS($B:$B,B497,$C:$C,C497)>1,"Duplicate","Unique") -> Unique | M497: =IF(COUNTIF(Payments_Raw!$B:$B,A497)=0,"Unpaid",IF(N497>=G497,"Paid",IF(N497>0,"Partial Payment",IF(COUNTIFS(Payments_Raw!$B:$B,A497,Payments_Raw!$F:$F,"Failed")>0,"Failed",IF(COUNTIFS(Payments_Raw!$B:$B,A497,Payments_Raw!$F:$F,"Pending")>0,"Pending","Unpaid"))))) -> Partial Payment | N497: =SUMIFS(Payments_Raw!$E:$E,Payments_Raw!$B:$B,A497,Payments_Raw!$F:$F,"Successful") -> 21569.02 | O497: =G497-N497 -> 1135.21 | P497: =IF(L497="Duplicate","Duplicate Invoice",IF(M497="Failed","Failed Payment",IF(M497="Pending","Pending Payment",IF(M497="Unpaid","Unpaid Invoice",IF(M497="Partial Payment","Amount Mismatch","No Exception"))))) -> Amount Mismatch | Q497: =IF(AND(G497<DATE(2026,10,14),M497<>"Paid"),"Overdue","Not Overdue") -> Overdue | S497: =COUNTIF(Invoice_Analysis!L:L,"Duplicate") -> 48
A498: IN00497 | B498: V011 | C498: INV-V011-45847 | D498: PO-975427 | E498: 46075 | F498: 46105 | G498: 17628.96 | H498: INR | I498: Modified | J498: No | K498: EDI | L498: =IF(COUNTIFS($B:$B,B498,$C:$C,C498)>1,"Duplicate","Unique") -> Unique | M498: =IF(COUNTIF(Payments_Raw!$B:$B,A498)=0,"Unpaid",IF(N498>=G498,"Paid",IF(N498>0,"Partial Payment",IF(COUNTIFS(Payments_Raw!$B:$B,A498,Payments_Raw!$F:$F,"Failed")>0,"Failed",IF(COUNTIFS(Payments_Raw!$B:$B,A498,Payments_Raw!$F:$F,"Pending")>0,"Pending","Unpaid"))))) -> Paid | N498: =SUMIFS(Payments_Raw!$E:$E,Payments_Raw!$B:$B,A498,Payments_Raw!$F:$F,"Successful") -> 17628.96 | O498: =G498-N498 -> 0 | P498: =IF(L498="Duplicate","Duplicate Invoice",IF(M498="Failed","Failed Payment",IF(M498="Pending","Pending Payment",IF(M498="Unpaid","Unpaid Invoice",IF(M498="Partial Payment","Amount Mismatch","No Exception"))))) -> No Exception | Q498: =IF(AND(G498<DATE(2026,10,14),M498<>"Paid"),"Overdue","Not Overdue") -> Not Overdue
A499: IN00498 | B499: V006 | C499: INV-V006-95634 | D499: PO-976052 | E499: 46215 | F499: 46230 | G499: 16383.44 | H499: INR | I499: Received | J499: No | K499: Email | L499: =IF(COUNTIFS($B:$B,B499,$C:$C,C499)>1,"Duplicate","Unique") -> Unique | M499: =IF(COUNTIF(Payments_Raw!$B:$B,A499)=0,"Unpaid",IF(N499>=G499,"Paid",IF(N499>0,"Partial Payment",IF(COUNTIFS(Payments_Raw!$B:$B,A499,Payments_Raw!$F:$F,"Failed")>0,"Failed",IF(COUNTIFS(Payments_Raw!$B:$B,A499,Payments_Raw!$F:$F,"Pending")>0,"Pending","Unpaid"))))) -> Paid | N499: =SUMIFS(Payments_Raw!$E:$E,Payments_Raw!$B:$B,A499,Payments_Raw!$F:$F,"Successful") -> 16383.44 | O499: =G499-N499 -> 0 | P499: =IF(L499="Duplicate","Duplicate Invoice",IF(M499="Failed","Failed Payment",IF(M499="Pending","Pending Payment",IF(M499="Unpaid","Unpaid Invoice",IF(M499="Partial Payment","Amount Mismatch","No Exception"))))) -> No Exception | Q499: =IF(AND(G499<DATE(2026,10,14),M499<>"Paid"),"Overdue","Not Overdue") -> Not Overdue
A500: IN00499 | B500: V017 | C500: INV-V017-73813 | D500: PO-931161 | E500: 46230 | F500: 46260 | G500: 8900.1 | H500: INR | I500: Approved | J500: No | K500: EDI | L500: =IF(COUNTIFS($B:$B,B500,$C:$C,C500)>1,"Duplicate","Unique") -> Unique | M500: =IF(COUNTIF(Payments_Raw!$B:$B,A500)=0,"Unpaid",IF(N500>=G500,"Paid",IF(N500>0,"Partial Payment",IF(COUNTIFS(Payments_Raw!$B:$B,A500,Payments_Raw!$F:$F,"Failed")>0,"Failed",IF(COUNTIFS(Payments_Raw!$B:$B,A500,Payments_Raw!$F:$F,"Pending")>0,"Pending","Unpaid"))))) -> Unpaid | N500: =SUMIFS(Payments_Raw!$E:$E,Payments_Raw!$B:$B,A500,Payments_Raw!$F:$F,"Successful") -> 0 | O500: =G500-N500 -> 8900.1 | P500: =IF(L500="Duplicate","Duplicate Invoice",IF(M500="Failed","Failed Payment",IF(M500="Pending","Pending Payment",IF(M500="Unpaid","Unpaid Invoice",IF(M500="Partial Payment","Amount Mismatch","No Exception"))))) -> Unpaid Invoice | Q500: =IF(AND(G500<DATE(2026,10,14),M500<>"Paid"),"Overdue","Not Overdue") -> Overdue
A501: IN00500 | B501: V005 | C501: INV-V005-37723 | D501: PO-257538 | E501: 46248 | F501: 46263 | G501: 47521.7 | H501: INR | I501: Received | J501: No | K501: EDI | L501: =IF(COUNTIFS($B:$B,B501,$C:$C,C501)>1,"Duplicate","Unique") -> Unique | M501: =IF(COUNTIF(Payments_Raw!$B:$B,A501)=0,"Unpaid",IF(N501>=G501,"Paid",IF(N501>0,"Partial Payment",IF(COUNTIFS(Payments_Raw!$B:$B,A501,Payments_Raw!$F:$F,"Failed")>0,"Failed",IF(COUNTIFS(Payments_Raw!$B:$B,A501,Payments_Raw!$F:$F,"Pending")>0,"Pending","Unpaid"))))) -> Paid | N501: =SUMIFS(Payments_Raw!$E:$E,Payments_Raw!$B:$B,A501,Payments_Raw!$F:$F,"Successful") -> 47521.7 | O501: =G501-N501 -> 0 | P501: =IF(L501="Duplicate","Duplicate Invoice",IF(M501="Failed","Failed Payment",IF(M501="Pending","Pending Payment",IF(M501="Unpaid","Unpaid Invoice",IF(M501="Partial Payment","Amount Mismatch","No Exception"))))) -> No Exception | Q501: =IF(AND(G501<DATE(2026,10,14),M501<>"Paid"),"Overdue","Not Overdue") -> Not Overdue
A502: IN00501 | B502: V006 | C502: INV-V006-21539 | D502: PO-235691 | E502: 46104 | F502: 46134 | G502: 12300.68 | H502: INR | I502: Approved | J502: No | K502: Supplier Portal | L502: =IF(COUNTIFS($B:$B,B502,$C:$C,C502)>1,"Duplicate","Unique") -> Duplicate | M502: =IF(COUNTIF(Payments_Raw!$B:$B,A502)=0,"Unpaid",IF(N502>=G502,"Paid",IF(N502>0,"Partial Payment",IF(COUNTIFS(Payments_Raw!$B:$B,A502,Payments_Raw!$F:$F,"Failed")>0,"Failed",IF(COUNTIFS(Payments_Raw!$B:$B,A502,Payments_Raw!$F:$F,"Pending")>0,"Pending","Unpaid"))))) -> Pending | N502: =SUMIFS(Payments_Raw!$E:$E,Payments_Raw!$B:$B,A502,Payments_Raw!$F:$F,"Successful") -> 0 | O502: =G502-N502 -> 12300.68 | P502: =IF(L502="Duplicate","Duplicate Invoice",IF(M502="Failed","Failed Payment",IF(M502="Pending","Pending Payment",IF(M502="Unpaid","Unpaid Invoice",IF(M502="Partial Payment","Amount Mismatch","No Exception"))))) -> Duplicate Invoice | Q502: =IF(AND(G502<DATE(2026,10,14),M502<>"Paid"),"Overdue","Not Overdue") -> Overdue
A503: IN00502 | B503: V008 | C503: INV-V008-38569 | D503: PO-587623 | E503: 46087 | F503: 46117 | G503: 11902.2 | H503: INR | I503: Modified | J503: No | K503: Email | L503: =IF(COUNTIFS($B:$B,B503,$C:$C,C503)>1,"Duplicate","Unique") -> Duplicate | M503: =IF(COUNTIF(Payments_Raw!$B:$B,A503)=0,"Unpaid",IF(N503>=G503,"Paid",IF(N503>0,"Partial Payment",IF(COUNTIFS(Payments_Raw!$B:$B,A503,Payments_Raw!$F:$F,"Failed")>0,"Failed",IF(COUNTIFS(Payments_Raw!$B:$B,A503,Payments_Raw!$F:$F,"Pending")>0,"Pending","Unpaid"))))) -> Paid | N503: =SUMIFS(Payments_Raw!$E:$E,Payments_Raw!$B:$B,A503,Payments_Raw!$F:$F,"Successful") -> 11902.2 | O503: =G503-N503 -> 0 | P503: =IF(L503="Duplicate","Duplicate Invoice",IF(M503="Failed","Failed Payment",IF(M503="Pending","Pending Payment",IF(M503="Unpaid","Unpaid Invoice",IF(M503="Partial Payment","Amount Mismatch","No Exception"))))) -> Duplicate Invoice | Q503: =IF(AND(G503<DATE(2026,10,14),M503<>"Paid"),"Overdue","Not Overdue") -> Not Overdue
A504: IN00503 | B504: V004 | C504: INV-V004-78662 | D504: PO-166974 | E504: 46040 | F504: 46070 | G504: 8455.07 | H504: INR | I504: Approved | J504: No | K504: EDI | L504: =IF(COUNTIFS($B:$B,B504,$C:$C,C504)>1,"Duplicate","Unique") -> Duplicate | M504: =IF(COUNTIF(Payments_Raw!$B:$B,A504)=0,"Unpaid",IF(N504>=G504,"Paid",IF(N504>0,"Partial Payment",IF(COUNTIFS(Payments_Raw!$B:$B,A504,Payments_Raw!$F:$F,"Failed")>0,"Failed",IF(COUNTIFS(Payments_Raw!$B:$B,A504,Payments_Raw!$F:$F,"Pending")>0,"Pending","Unpaid"))))) -> Pending | N504: =SUMIFS(Payments_Raw!$E:$E,Payments_Raw!$B:$B,A504,Payments_Raw!$F:$F,"Successful") -> 0 | O504: =G504-N504 -> 8455.07 | P504: =IF(L504="Duplicate","Duplicate Invoice",IF(M504="Failed","Failed Payment",IF(M504="Pending","Pending Payment",IF(M504="Unpaid","Unpaid Invoice",IF(M504="Partial Payment","Amount Mismatch","No Exception"))))) -> Duplicate Invoice | Q504: =IF(AND(G504<DATE(2026,10,14),M504<>"Paid"),"Overdue","Not Overdue") -> Overdue
A505: IN00504 | B505: V008 | C505: INV-V008-49608 | D505: PO-780776 | E505: 46057 | F505: 46087 | G505: 15928.85 | H505: INR | I505: Approved | J505: Yes | K505: Email | L505: =IF(COUNTIFS($B:$B,B505,$C:$C,C505)>1,"Duplicate","Unique") -> Duplicate | M505: =IF(COUNTIF(Payments_Raw!$B:$B,A505)=0,"Unpaid",IF(N505>=G505,"Paid",IF(N505>0,"Partial Payment",IF(COUNTIFS(Payments_Raw!$B:$B,A505,Payments_Raw!$F:$F,"Failed")>0,"Failed",IF(COUNTIFS(Payments_Raw!$B:$B,A505,Payments_Raw!$F:$F,"Pending")>0,"Pending","Unpaid"))))) -> Paid | N505: =SUMIFS(Payments_Raw!$E:$E,Payments_Raw!$B:$B,A505,Payments_Raw!$F:$F,"Successful") -> 15928.85 | O505: =G505-N505 -> 0 | P505: =IF(L505="Duplicate","Duplicate Invoice",IF(M505="Failed","Failed Payment",IF(M505="Pending","Pending Payment",IF(M505="Unpaid","Unpaid Invoice",IF(M505="Partial Payment","Amount Mismatch","No Exception"))))) -> Duplicate Invoice | Q505: =IF(AND(G505<DATE(2026,10,14),M505<>"Paid"),"Overdue","Not Overdue") -> Not Overdue
A506: IN00505 | B506: V005 | C506: INV-V005-61505 | D506: PO-746447 | E506: 46190 | F506: 46220 | G506: 23292.45 | H506: INR | I506: Modified | J506: No | K506: Supplier Portal | L506: =IF(COUNTIFS($B:$B,B506,$C:$C,C506)>1,"Duplicate","Unique") -> Duplicate | M506: =IF(COUNTIF(Payments_Raw!$B:$B,A506)=0,"Unpaid",IF(N506>=G506,"Paid",IF(N506>0,"Partial Payment",IF(COUNTIFS(Payments_Raw!$B:$B,A506,Payments_Raw!$F:$F,"Failed")>0,"Failed",IF(COUNTIFS(Payments_Raw!$B:$B,A506,Payments_Raw!$F:$F,"Pending")>0,"Pending","Unpaid"))))) -> Unpaid | N506: =SUMIFS(Payments_Raw!$E:$E,Payments_Raw!$B:$B,A506,Payments_Raw!$F:$F,"Successful") -> 0 | O506: =G506-N506 -> 23292.45 | P506: =IF(L506="Duplicate","Duplicate Invoice",IF(M506="Failed","Failed Payment",IF(M506="Pending","Pending Payment",IF(M506="Unpaid","Unpaid Invoice",IF(M506="Partial Payment","Amount Mismatch","No Exception"))))) -> Duplicate Invoice | Q506: =IF(AND(G506<DATE(2026,10,14),M506<>"Paid"),"Overdue","Not Overdue") -> Overdue
A507: IN00506 | B507: V019 | C507: INV-V019-25704 | D507: PO-813763 | E507: 46061 | F507: 46091 | G507: 11868.83 | H507: INR | I507: Approved | J507: No | K507: Email | L507: =IF(COUNTIFS($B:$B,B507,$C:$C,C507)>1,"Duplicate","Unique") -> Duplicate | M507: =IF(COUNTIF(Payments_Raw!$B:$B,A507)=0,"Unpaid",IF(N507>=G507,"Paid",IF(N507>0,"Partial Payment",IF(COUNTIFS(Payments_Raw!$B:$B,A507,Payments_Raw!$F:$F,"Failed")>0,"Failed",IF(COUNTIFS(Payments_Raw!$B:$B,A507,Payments_Raw!$F:$F,"Pending")>0,"Pending","Unpaid"))))) -> Paid | N507: =SUMIFS(Payments_Raw!$E:$E,Payments_Raw!$B:$B,A507,Payments_Raw!$F:$F,"Successful") -> 11868.83 | O507: =G507-N507 -> 0 | P507: =IF(L507="Duplicate","Duplicate Invoice",IF(M507="Failed","Failed Payment",IF(M507="Pending","Pending Payment",IF(M507="Unpaid","Unpaid Invoice",IF(M507="Partial Payment","Amount Mismatch","No Exception"))))) -> Duplicate Invoice | Q507: =IF(AND(G507<DATE(2026,10,14),M507<>"Paid"),"Overdue","Not Overdue") -> Not Overdue
A508: IN00507 | B508: V012 | C508: INV-V012-95191 | D508: PO-451577 | E508: 46137 | F508: 46167 | G508: 821.31 | H508: INR | I508: Modified | J508: Yes | K508: Supplier Portal | L508: =IF(COUNTIFS($B:$B,B508,$C:$C,C508)>1,"Duplicate","Unique") -> Duplicate | M508: =IF(COUNTIF(Payments_Raw!$B:$B,A508)=0,"Unpaid",IF(N508>=G508,"Paid",IF(N508>0,"Partial Payment",IF(COUNTIFS(Payments_Raw!$B:$B,A508,Payments_Raw!$F:$F,"Failed")>0,"Failed",IF(COUNTIFS(Payments_Raw!$B:$B,A508,Payments_Raw!$F:$F,"Pending")>0,"Pending","Unpaid"))))) -> Paid | N508: =SUMIFS(Payments_Raw!$E:$E,Payments_Raw!$B:$B,A508,Payments_Raw!$F:$F,"Successful") -> 821.31 | O508: =G508-N508 -> 0 | P508: =IF(L508="Duplicate","Duplicate Invoice",IF(M508="Failed","Failed Payment",IF(M508="Pending","Pending Payment",IF(M508="Unpaid","Unpaid Invoice",IF(M508="Partial Payment","Amount Mismatch","No Exception"))))) -> Duplicate Invoice | Q508: =IF(AND(G508<DATE(2026,10,14),M508<>"Paid"),"Overdue","Not Overdue") -> Not Overdue
A509: IN00508 | B509: V019 | C509: INV-V019-74517 | D509: PO-668458 | E509: 46095 | F509: 46125 | G509: 14130.15 | H509: INR | I509: Approved | J509: No | K509: Email | L509: =IF(COUNTIFS($B:$B,B509,$C:$C,C509)>1,"Duplicate","Unique") -> Duplicate | M509: =IF(COUNTIF(Payments_Raw!$B:$B,A509)=0,"Unpaid",IF(N509>=G509,"Paid",IF(N509>0,"Partial Payment",IF(COUNTIFS(Payments_Raw!$B:$B,A509,Payments_Raw!$F:$F,"Failed")>0,"Failed",IF(COUNTIFS(Payments_Raw!$B:$B,A509,Payments_Raw!$F:$F,"Pending")>0,"Pending","Unpaid"))))) -> Paid | N509: =SUMIFS(Payments_Raw!$E:$E,Payments_Raw!$B:$B,A509,Payments_Raw!$F:$F,"Successful") -> 14130.15 | O509: =G509-N509 -> 0 | P509: =IF(L509="Duplicate","Duplicate Invoice",IF(M509="Failed","Failed Payment",IF(M509="Pending","Pending Payment",IF(M509="Unpaid","Unpaid Invoice",IF(M509="Partial Payment","Amount Mismatch","No Exception"))))) -> Duplicate Invoice | Q509: =IF(AND(G509<DATE(2026,10,14),M509<>"Paid"),"Overdue","Not Overdue") -> Not Overdue
... A525: IN00524 | B525: V017 | C525: INV-V017-60293 | D525: PO-543588 | E525: 46222 | F525: 46252 | G525: 10525.79 | H525: INR | I525: Received | J525: No | K525: EDI | L525: =IF(COUNTIFS($B:$B,B525,$C:$C,C525)>1,"Duplicate","Unique") -> Duplicate | M525: =IF(COUNTIF(Payments_Raw!$B:$B,A525)=0,"Unpaid",IF(N525>=G525,"Paid",IF(N525>0,"Partial Payment",IF(COUNTIFS(Payments_Raw!$B:$B,A525,Payments_Raw!$F:$F,"Failed")>0,"Failed",IF(COUNTIFS(Payments_Raw!$B:$B,A525,Payments_Raw!$F:$F,"Pending")>0,"Pending","Unpaid"))))) -> Paid | N525: =SUMIFS(Payments_Raw!$E:$E,Payments_Raw!$B:$B,A525,Payments_Raw!$F:$F,"Successful") -> 10525.79 | O525: =G525-N525 -> 0 | P525: =IF(L525="Duplicate","Duplicate Invoice",IF(M525="Failed","Failed Payment",IF(M525="Pending","Pending Payment",IF(M525="Unpaid","Unpaid Invoice",IF(M525="Partial Payment","Amount Mismatch","No Exception"))))) -> Duplicate Invoice | Q525: =IF(AND(G525<DATE(2026,10,14),M525<>"Paid"),"Overdue","Not Overdue") -> Not Overdue
